Workbook
Name Slicer_smoker2: #N/A
Name Slicer_Weight_status: #N/A

Sheet Customer
A1: Customer ID | B1: Title | C1: First | D1: Last
A2: Id1 | B2: Ms | C2: Kelly | D2: Hawks
A3: Id2 | B3: Mr | C3: Matthew | D3: Lehner
A4: Id3 | B4: Mr | C4: Phil | D4: Lu
A5: Id4 | B5: Ms | C5: Kelsey | D5: Osborne
A6: Id5 | B6: Ms | C6: Kristyn | D6: Kadala
A7: Id6 | B7: Mr | C7: Russell | D7: Baker
A8: Id7 | B8: Mr | C8: Scott | D8: Macpherson
A9: Id8 | B9: Mr | C9: Stephen | D9: Hallman
A10: Id9 | B10: Mr | C10: Patrick | D10: Moran
A11: Id10 | B11: Ms | C11: Brooke | D11: Benner
A12: Id11 | B12: Ms | C12: Andrea Paola | D12: Fierro Vargas
... A2336: Id2335 | B2336: Mr | C2336: Aaron | D2336: German

Sheet Hospitalisation
A1: Customer ID | B1: children | C1: charges | D1: Hospital tier | E1: State ID | F1: Hospital tier2 | G1: City tier | H1: Yea | I1: Hsp Tier | J1: Cty Tier | K1: StateID | L1: Age | M1: Date of Birth2
A2: Id1 | B2: 0 | C2: 63770.43 | D2: tier - 1 | E2: R1013 | F2: tier - 1 | G2: tier - 3 | H2: 1968 | I2: {=IF(D2="", INDEX($D$2:$D$2345, MODE(MATCH(IF($D$2:$D$2345<>"",$D$2:$D$2345), IF($D$2:$D$2345<>"",$D$2:$D$2345),0))), D2)} -> tier - 1 | J2: {=IF(G2="", INDEX($G$2:$G$2345, MODE(MATCH(IF($G$2:$G$2345<>"",$G$2:$G$2345), IF($G$2:$G$2345<>"",$G$2:$G$2345),0))), G2)} -> tier - 3 | K2: {=IF(E2="", INDEX($E$2:$E$2345, MODE(MATCH(IF($E$2:$E$2345<>"",$E$2:$E$2345), IF($E$2:$E$2345<>"",$E$2:$E$2345),0))), E2)} -> R1013 | L2: =INT(YEARFRAC(M2,DATE(2023,6,8))) -> 39 | M2: 30601
A3: Id10 | B3: 0 | C3: 48885.14 | D3: tier - 1 | E3: R1013 | F3: tier - 1 | G3: tier - 2 | H3: 1978 | I3: {=IF(D3="", INDEX($D$2:$D$2345, MODE(MATCH(IF($D$2:$D$2345<>"",$D$2:$D$2345), IF($D$2:$D$2345<>"",$D$2:$D$2345),0))), D3)} -> tier - 1 | J3: {=IF(G3="", INDEX($G$2:$G$2345, MODE(MATCH(IF($G$2:$G$2345<>"",$G$2:$G$2345), IF($G$2:$G$2345<>"",$G$2:$G$2345),0))), G3)} -> tier - 2 | K3: {=IF(E3="", INDEX($E$2:$E$2345, MODE(MATCH(IF($E$2:$E$2345<>"",$E$2:$E$2345), IF($E$2:$E$2345<>"",$E$2:$E$2345),0))), E3)} -> R1013 | L3: =INT(YEARFRAC(M3,DATE(2023,6,8))) -> 59 | M3: 23374
A4: Id100 | B4: 2 | C4: 40284.38 | D4: tier - 1 | E4: R1012 | F4: tier - 1 | G4: tier - 3 | H4: 1977 | I4: {=IF(D4="", INDEX($D$2:$D$2345, MODE(MATCH(IF($D$2:$D$2345<>"",$D$2:$D$2345), IF($D$2:$D$2345<>"",$D$2:$D$2345),0))), D4)} -> tier - 1 | J4: {=IF(G4="", INDEX($G$2:$G$2345, MODE(MATCH(IF($G$2:$G$2345<>"",$G$2:$G$2345), IF($G$2:$G$2345<>"",$G$2:$G$2345),0))), G4)} -> tier - 3 | K4: {=IF(E4="", INDEX($E$2:$E$2345, MODE(MATCH(IF($E$2:$E$2345<>"",$E$2:$E$2345), IF($E$2:$E$2345<>"",$E$2:$E$2345),0))), E4)} -> R1012 | L4: =INT(YEARFRAC(M4,DATE(2023,6,8))) -> 60 | M4: 22824
A5: Id1000 | B5: 3 | C5: 11250.43 | D5: tier - 3 | E5: R1026 | F5: tier - 3 | G5: tier - 2 | H5: 1989 | I5: {=IF(D5="", INDEX($D$2:$D$2345, MODE(MATCH(IF($D$2:$D$2345<>"",$D$2:$D$2345), IF($D$2:$D$2345<>"",$D$2:$D$2345),0))), D5)} -> tier - 3 | J5: {=IF(G5="", INDEX($G$2:$G$2345, MODE(MATCH(IF($G$2:$G$2345<>"",$G$2:$G$2345), IF($G$2:$G$2345<>"",$G$2:$G$2345),0))), G5)} -> tier - 2 | K5: {=IF(E5="", INDEX($E$2:$E$2345, MODE(MATCH(IF($E$2:$E$2345<>"",$E$2:$E$2345), IF($E$2:$E$2345<>"",$E$2:$E$2345),0))), E5)} -> R1026 | L5: =INT(YEARFRAC(M5,DATE(2023,6,8))) -> 53 | M5: 25554
A6: Id1001 | B6: 2 | C6: 11244.38 | D6: tier - 3 | E6: R1016 | F6: tier - 3 | G6: tier - 1 | H6: 1969 | I6: {=IF(D6="", INDEX($D$2:$D$2345, MODE(MATCH(IF($D$2:$D$2345<>"",$D$2:$D$2345), IF($D$2:$D$2345<>"",$D$2:$D$2345),0))), D6)} -> tier - 3 | J6: {=IF(G6="", INDEX($G$2:$G$2345, MODE(MATCH(IF($G$2:$G$2345<>"",$G$2:$G$2345), IF($G$2:$G$2345<>"",$G$2:$G$2345),0))), G6)} -> tier - 1 | K6: {=IF(E6="", INDEX($E$2:$E$2345, MODE(MATCH(IF($E$2:$E$2345<>"",$E$2:$E$2345), IF($E$2:$E$2345<>"",$E$2:$E$2345),0))), E6)} -> R1016 | L6: =INT(YEARFRAC(M6,DATE(2023,6,8))) -> 33 | M6: 32872
A7: Id1002 | B7: 2 | C7: 11217.35 | D7: tier - 3 | E7: R1025 | F7: tier - 3 | G7: tier - 2 | H7: 1976 | I7: {=IF(D7="", INDEX($D$2:$D$2345, MODE(MATCH(IF($D$2:$D$2345<>"",$D$2:$D$2345), IF($D$2:$D$2345<>"",$D$2:$D$2345),0))), D7)} -> tier - 3 | J7: {=IF(G7="", INDEX($G$2:$G$2345, MODE(MATCH(IF($G$2:$G$2345<>"",$G$2:$G$2345), IF($G$2:$G$2345<>"",$G$2:$G$2345),0))), G7)} -> tier - 2 | K7: {=IF(E7="", INDEX($E$2:$E$2345, MODE(MATCH(IF($E$2:$E$2345<>"",$E$2:$E$2345), IF($E$2:$E$2345<>"",$E$2:$E$2345),0))), E7)} -> R1025 | L7: =INT(YEARFRAC(M7,DATE(2023,6,8))) -> 53 | M7: 25382
A8: Id1003 | B8: 2 | C8: 11187.66 | D8: tier - 3 | E8: R1012 | F8: tier - 3 | G8: tier - 2 | H8: 1970 | I8: {=IF(D8="", INDEX($D$2:$D$2345, MODE(MATCH(IF($D$2:$D$2345<>"",$D$2:$D$2345), IF($D$2:$D$2345<>"",$D$2:$D$2345),0))), D8)} -> tier - 3 | J8: {=IF(G8="", INDEX($G$2:$G$2345, MODE(MATCH(IF($G$2:$G$2345<>"",$G$2:$G$2345), IF($G$2:$G$2345<>"",$G$2:$G$2345),0))), G8)} -> tier - 2 | K8: {=IF(E8="", INDEX($E$2:$E$2345, MODE(MATCH(IF($E$2:$E$2345<>"",$E$2:$E$2345), IF($E$2:$E$2345<>"",$E$2:$E$2345),0))), E8)} -> R1012 | L8: =INT(YEARFRAC(M8,DATE(2023,6,8))) -> 46 | M8: 27925
A9: Id1004 | B9: 0 | C9: 11186.2 | D9: tier - 3 | E9: R1021 | F9: tier - 3 | G9: tier - 2 | H9: 1972 | I9: {=IF(D9="", INDEX($D$2:$D$2345, MODE(MATCH(IF($D$2:$D$2345<>"",$D$2:$D$2345), IF($D$2:$D$2345<>"",$D$2:$D$2345),0))), D9)} -> tier - 3 | J9: {=IF(G9="", INDEX($G$2:$G$2345, MODE(MATCH(IF($G$2:$G$2345<>"",$G$2:$G$2345), IF($G$2:$G$2345<>"",$G$2:$G$2345),0))), G9)} -> tier - 2 | K9: {=IF(E9="", INDEX($E$2:$E$2345, MODE(MATCH(IF($E$2:$E$2345<>"",$E$2:$E$2345), IF($E$2:$E$2345<>"",$E$2:$E$2345),0))), E9)} -> R1021 | L9: =INT(YEARFRAC(M9,DATE(2023,6,8))) -> 52 | M9: 25814
A10: Id1005 | B10: 0 | C10: 11165.42 | D10: tier - 3 | E10: R1016 | F10: tier - 3 | G10: tier - 1 | H10: 1966 | I10: {=IF(D10="", INDEX($D$2:$D$2345, MODE(MATCH(IF($D$2:$D$2345<>"",$D$2:$D$2345), IF($D$2:$D$2345<>"",$D$2:$D$2345),0))), D10)} -> tier - 3 | J10: {=IF(G10="", INDEX($G$2:$G$2345, MODE(MATCH(IF($G$2:$G$2345<>"",$G$2:$G$2345), IF($G$2:$G$2345<>"",$G$2:$G$2345),0))), G10)} -> tier - 1 | K10: {=IF(E10="", INDEX($E$2:$E$2345, MODE(MATCH(IF($E$2:$E$2345<>"",$E$2:$E$2345), IF($E$2:$E$2345<>"",$E$2:$E$2345),0))), E10)} -> R1016 | L10: =INT(YEARFRAC(M10,DATE(2023,6,8))) -> 50 | M10: 26517
A11: Id1006 | B11: 2 | C11: 11163.57 | D11: tier - 3 | E11: R1011 | F11: tier - 3 | G11: tier - 2 | H11: 1969 | I11: {=IF(D11="", INDEX($D$2:$D$2345, MODE(MATCH(IF($D$2:$D$2345<>"",$D$2:$D$2345), IF($D$2:$D$2345<>"",$D$2:$D$2345),0))), D11)} -> tier - 3 | J11: {=IF(G11="", INDEX($G$2:$G$2345, MODE(MATCH(IF($G$2:$G$2345<>"",$G$2:$G$2345), IF($G$2:$G$2345<>"",$G$2:$G$2345),0))), G11)} -> tier - 2 | K11: {=IF(E11="", INDEX($E$2:$E$2345, MODE(MATCH(IF($E$2:$E$2345<>"",$E$2:$E$2345), IF($E$2:$E$2345<>"",$E$2:$E$2345),0))), E11)} -> R1011 | L11: =INT(YEARFRAC(M11,DATE(2023,6,8))) -> 56 | M11: 24283
A12: Id1007 | B12: 2 | C12: 11150.78 | D12: tier - 3 | E12: R1011 | F12: tier - 3 | G12: tier - 2 | H12: 1969 | I12: {=IF(D12="", INDEX($D$2:$D$2345, MODE(MATCH(IF($D$2:$D$2345<>"",$D$2:$D$2345), IF($D$2:$D$2345<>"",$D$2:$D$2345),0))), D12)} -> tier - 3 | J12: {=IF(G12="", INDEX($G$2:$G$2345, MODE(MATCH(IF($G$2:$G$2345<>"",$G$2:$G$2345), IF($G$2:$G$2345<>"",$G$2:$G$2345),0))), G12)} -> tier - 2 | K12: {=IF(E12="", INDEX($E$2:$E$2345, MODE(MATCH(IF($E$2:$E$2345<>"",$E$2:$E$2345), IF($E$2:$E$2345<>"",$E$2:$E$2345),0))), E12)} -> R1011 | L12: =INT(YEARFRAC(M12,DATE(2023,6,8))) -> 53 | M12: 25537
A13: Id1008 | B13: 2 | C13: 11103.33 | D13: tier - 3 | E13: R1021 | F13: tier - 3 | G13: tier - 1 | H13: 1980 | I13: {=IF(D13="", INDEX($D$2:$D$2345, MODE(MATCH(IF($D$2:$D$2345<>"",$D$2:$D$2345), IF($D$2:$D$2345<>"",$D$2:$D$2345),0))), D13)} -> tier - 3 | J13: {=IF(G13="", INDEX($G$2:$G$2345, MODE(MATCH(IF($G$2:$G$2345<>"",$G$2:$G$2345), IF($G$2:$G$2345<>"",$G$2:$G$2345),0))), G13)} -> tier - 1 | K13: {=IF(E13="", INDEX($E$2:$E$2345, MODE(MATCH(IF($E$2:$E$2345<>"",$E$2:$E$2345), IF($E$2:$E$2345<>"",$E$2:$E$2345),0))), E13)} -> R1021 | L13: =INT(YEARFRAC(M13,DATE(2023,6,8))) -> 53 | M13: 25435
... A320: Id1285 | B320: 1 | C320: 8551.35 | D320: tier - 2 | E320: R1011 | F320: tier - 2 | G320: tier - 2 | H320: 1975 | I320: {=IF(D320="", INDEX($D$2:$D$2345, MODE(MATCH(IF($D$2:$D$2345<>"",$D$2:$D$2345), IF($D$2:$D$2345<>"",$D$2:$D$2345),0))), D320)} -> tier - 2 | J320: {=IF(G320="", INDEX($G$2:$G$2345, MODE(MATCH(IF($G$2:$G$2345<>"",$G$2:$G$2345), IF($G$2:$G$2345<>"",$G$2:$G$2345),0))), G320)} -> tier - 2 | K320: {=IF(E320="", INDEX($E$2:$E$2345, MODE(MATCH(IF($E$2:$E$2345<>"",$E$2:$E$2345), IF($E$2:$E$2345<>"",$E$2:$E$2345),0))), E320)} -> R1011 | L320: =INT(YEARFRAC(M320,DATE(2023,6,8))) -> 47 | M320: 27612
A321: Id1286 | B321: 1 | C321: 8547.69 | D321: tier - 2 | E321: R1013 | F321: tier - 2 | G321: tier - 1 | I321: {=IF(D321="", INDEX($D$2:$D$2345, MODE(MATCH(IF($D$2:$D$2345<>"",$D$2:$D$2345), IF($D$2:$D$2345<>"",$D$2:$D$2345),0))), D321)} -> tier - 2 | J321: {=IF(G321="", INDEX($G$2:$G$2345, MODE(MATCH(IF($G$2:$G$2345<>"",$G$2:$G$2345), IF($G$2:$G$2345<>"",$G$2:$G$2345),0))), G321)} -> tier - 1 | K321: {=IF(E321="", INDEX($E$2:$E$2345, MODE(MATCH(IF($E$2:$E$2345<>"",$E$2:$E$2345), IF($E$2:$E$2345<>"",$E$2:$E$2345),0))), E321)} -> R1013 | L321: =INT(YEARFRAC(M321,DATE(2023,6,8))) -> 47 | M321: 27740
A322: Id1287 | B322: 1 | C322: 8539.67 | D322: tier - 2 | E322: R1011 | F322: tier - 2 | G322: tier - 3 | H322: 1975 | I322: {=IF(D322="", INDEX($D$2:$D$2345, MODE(MATCH(IF($D$2:$D$2345<>"",$D$2:$D$2345), IF($D$2:$D$2345<>"",$D$2:$D$2345),0))), D322)} -> tier - 2 | J322: {=IF(G322="", INDEX($G$2:$G$2345, MODE(MATCH(IF($G$2:$G$2345<>"",$G$2:$G$2345), IF($G$2:$G$2345<>"",$G$2:$G$2345),0))), G322)} -> tier - 3 | K322: {=IF(E322="", INDEX($E$2:$E$2345, MODE(MATCH(IF($E$2:$E$2345<>"",$E$2:$E$2345), IF($E$2:$E$2345<>"",$E$2:$E$2345),0))), E322)} -> R1011 | L322: =INT(YEARFRAC(M322,DATE(2023,6,8))) -> 39 | M322: 30626
A323: Id1288 | B323: 3 | C323: 8538.29 | D323: tier - 2 | E323: R1024 | F323: tier - 2 | G323: tier - 3 | H323: 1981 | I323: {=IF(D323="", INDEX($D$2:$D$2345, MODE(MATCH(IF($D$2:$D$2345<>"",$D$2:$D$2345), IF($D$2:$D$2345<>"",$D$2:$D$2345),0))), D323)} -> tier - 2 | J323: {=IF(G323="", INDEX($G$2:$G$2345, MODE(MATCH(IF($G$2:$G$2345<>"",$G$2:$G$2345), IF($G$2:$G$2345<>"",$G$2:$G$2345),0))), G323)} -> tier - 3 | K323: {=IF(E323="", INDEX($E$2:$E$2345, MODE(MATCH(IF($E$2:$E$2345<>"",$E$2:$E$2345), IF($E$2:$E$2345<>"",$E$2:$E$2345),0))), E323)} -> R1024 | L323: =INT(YEARFRAC(M323,DATE(2023,6,8))) -> 47 | M323: 27755
A324: Id1289 | B324: 0 | C324: 8534.67 | D324: tier - 2 | E324: R1024 | F324: tier - 2 | G324: tier - 3 | I324: {=IF(D324="", INDEX($D$2:$D$2345, MODE(MATCH(IF($D$2:$D$2345<>"",$D$2:$D$2345), IF($D$2:$D$2345<>"",$D$2:$D$2345),0))), D324)} -> tier - 2 | J324: {=IF(G324="", INDEX($G$2:$G$2345, MODE(MATCH(IF($G$2:$G$2345<>"",$G$2:$G$2345), IF($G$2:$G$2345<>"",$G$2:$G$2345),0))), G324)} -> tier - 3 | K324: {=IF(E324="", INDEX($E$2:$E$2345, MODE(MATCH(IF($E$2:$E$2345<>"",$E$2:$E$2345), IF($E$2:$E$2345<>"",$E$2:$E$2345),0))), E324)} -> R1024 | L324: =INT(YEARFRAC(M324,DATE(2023,6,8))) -> 41 | M324: 29791
A325: Id129 | B325: 1 | C325: 39047.29 | D325: tier - 1 | E325: R1017 | F325: tier - 1 | G325: tier - 3 | H325: 1985 | I325: {=IF(D325="", INDEX($D$2:$D$2345, MODE(MATCH(IF($D$2:$D$2345<>"",$D$2:$D$2345), IF($D$2:$D$2345<>"",$D$2:$D$2345),0))), D325)} -> tier - 1 | J325: {=IF(G325="", INDEX($G$2:$G$2345, MODE(MATCH(IF($G$2:$G$2345<>"",$G$2:$G$2345), IF($G$2:$G$2345<>"",$G$2:$G$2345),0))), G325)} -> tier - 3 | K325: {=IF(E325="", INDEX($E$2:$E$2345, MODE(MATCH(IF($E$2:$E$2345<>"",$E$2:$E$2345), IF($E$2:$E$2345<>"",$E$2:$E$2345),0))), E325)} -> R1017 | L325: =INT(YEARFRAC(M325,DATE(2023,6,8))) -> 40 | M325: 30214
A326: Id1290 | B326: 2 | C326: 8527.53 | D326: tier - 2 | E326: R1013 | F326: tier - 2 | G326: tier - 2 | H326: 1977 | I326: {=IF(D326="", INDEX($D$2:$D$2345, MODE(MATCH(IF($D$2:$D$2345<>"",$D$2:$D$2345), IF($D$2:$D$2345<>"",$D$2:$D$2345),0))), D326)} -> tier - 2 | J326: {=IF(G326="", INDEX($G$2:$G$2345, MODE(MATCH(IF($G$2:$G$2345<>"",$G$2:$G$2345), IF($G$2:$G$2345<>"",$G$2:$G$2345),0))), G326)} -> tier - 2 | K326: {=IF(E326="", INDEX($E$2:$E$2345, MODE(MATCH(IF($E$2:$E$2345<>"",$E$2:$E$2345), IF($E$2:$E$2345<>"",$E$2:$E$2345),0))), E326)} -> R1013 | L326: =INT(YEARFRAC(M326,DATE(2023,6,8))) -> 39 | M326: 30523
A327: Id1291 | B327: 3 | C327: 8522 | D327: tier - 2 | E327: R1011 | F327: tier - 2 | G327: tier - 2 | H327: 1979 | I327: {=IF(D327="", INDEX($D$2:$D$2345, MODE(MATCH(IF($D$2:$D$2345<>"",$D$2:$D$2345), IF($D$2:$D$2345<>"",$D$2:$D$2345),0))), D327)} -> tier - 2 | J327: {=IF(G327="", INDEX($G$2:$G$2345, MODE(MATCH(IF($G$2:$G$2345<>"",$G$2:$G$2345), IF($G$2:$G$2345<>"",$G$2:$G$2345),0))), G327)} -> tier - 2 | K327: {=IF(E327="", INDEX($E$2:$E$2345, MODE(MATCH(IF($E$2:$E$2345<>"",$E$2:$E$2345), IF($E$2:$E$2345<>"",$E$2:$E$2345),0))), E327)} -> R1011 | L327: =INT(YEARFRAC(M327,DATE(2023,6,8))) -> 45 | M327: 28350
A328: Id1292 | B328: 2 | C328: 8520.03 | D328: tier - 2 | E328: R1011 | F328: tier - 2 | G328: tier - 3 | H328: 1977 | I328: {=IF(D328="", INDEX($D$2:$D$2345, MODE(MATCH(IF($D$2:$D$2345<>"",$D$2:$D$2345), IF($D$2:$D$2345<>"",$D$2:$D$2345),0))), D328)} -> tier - 2 | J328: {=IF(G328="", INDEX($G$2:$G$2345, MODE(MATCH(IF($G$2:$G$2345<>"",$G$2:$G$2345), IF($G$2:$G$2345<>"",$G$2:$G$2345),0))), G328)} -> tier - 3 | K328: {=IF(E328="", INDEX($E$2:$E$2345, MODE(MATCH(IF($E$2:$E$2345<>"",$E$2:$E$2345), IF($E$2:$E$2345<>"",$E$2:$E$2345),0))), E328)} -> R1011 | L328: =INT(YEARFRAC(M328,DATE(2023,6,8))) -> 43 | M328: 29218
A329: Id1293 | B329: 2 | C329: 8516.83 | D329: tier - 2 | E329: R1013 | F329: tier - 2 | G329: tier - 1 | H329: 1977 | I329: {=IF(D329="", INDEX($D$2:$D$2345, MODE(MATCH(IF($D$2:$D$2345<>"",$D$2:$D$2345), IF($D$2:$D$2345<>"",$D$2:$D$2345),0))), D329)} -> tier - 2 | J329: {=IF(G329="", INDEX($G$2:$G$2345, MODE(MATCH(IF($G$2:$G$2345<>"",$G$2:$G$2345), IF($G$2:$G$2345<>"",$G$2:$G$2345),0))), G329)} -> tier - 1 | K329: {=IF(E329="", INDEX($E$2:$E$2345, MODE(MATCH(IF($E$2:$E$2345<>"",$E$2:$E$2345), IF($E$2:$E$2345<>"",$E$2:$E$2345),0))), E329)} -> R1013 | L329: =INT(YEARFRAC(M329,DATE(2023,6,8))) -> 45 | M329: 28297
A330: Id1294 | B330: 2 | C330: 8515.76 | D330: tier - 2 | E330: R1013 | F330: tier - 2 | G330: tier - 2 | H330: 1977 | I330: {=IF(D330="", INDEX($D$2:$D$2345, MODE(MATCH(IF($D$2:$D$2345<>"",$D$2:$D$2345), IF($D$2:$D$2345<>"",$D$2:$D$2345),0))), D330)} -> tier - 2 | J330: {=IF(G330="", INDEX($G$2:$G$2345, MODE(MATCH(IF($G$2:$G$2345<>"",$G$2:$G$2345), IF($G$2:$G$2345<>"",$G$2:$G$2345),0))), G330)} -> tier - 2 | K330: {=IF(E330="", INDEX($E$2:$E$2345, MODE(MATCH(IF($E$2:$E$2345<>"",$E$2:$E$2345), IF($E$2:$E$2345<>"",$E$2:$E$2345),0))), E330)} -> R1013 | L330: =INT(YEARFRAC(M330,DATE(2023,6,8))) -> 45 | M330: 28485
A331: Id1295 | B331: 0 | C331: 8471.65 | D331: tier - 2 | E331: R1012 | F331: tier - 2 | G331: tier - 1 | H331: 1993 | I331: {=IF(D331="", INDEX($D$2:$D$2345, MODE(MATCH(IF($D$2:$D$2345<>"",$D$2:$D$2345), IF($D$2:$D$2345<>"",$D$2:$D$2345),0))), D331)} -> tier - 2 | J331: {=IF(G331="", INDEX($G$2:$G$2345, MODE(MATCH(IF($G$2:$G$2345<>"",$G$2:$G$2345), IF($G$2:$G$2345<>"",$G$2:$G$2345),0))), G331)} -> tier - 1 | K331: {=IF(E331="", INDEX($E$2:$E$2345, MODE(MATCH(IF($E$2:$E$2345<>"",$E$2:$E$2345), IF($E$2:$E$2345<>"",$E$2:$E$2345),0))), E331)} -> R1012 | L331: =INT(YEARFRAC(M331,DATE(2023,6,8))) -> 45 | M331: 28439
A332: Id1296 | B332: 0 | C332: 8466.35 | D332: tier - 2 | E332: R1012 | F332: tier - 2 | G332: tier - 2 | H332: 1992 | I332: {=IF(D332="", INDEX($D$2:$D$2345, MODE(MATCH(IF($D$2:$D$2345<>"",$D$2:$D$2345), IF($D$2:$D$2345<>"",$D$2:$D$2345),0))), D332)} -> tier - 2 | J332: {=IF(G332="", INDEX($G$2:$G$2345, MODE(MATCH(IF($G$2:$G$2345<>"",$G$2:$G$2345), IF($G$2:$G$2345<>"",$G$2:$G$2345),0))), G332)} -> tier - 2 | K332: {=IF(E332="", INDEX($E$2:$E$2345, MODE(MATCH(IF($E$2:$E$2345<>"",$E$2:$E$2345), IF($E$2:$E$2345<>"",$E$2:$E$2345),0))), E332)} -> R1012 | L332: =INT(YEARFRAC(M332,DATE(2023,6,8))) -> 29 | M332: 34221
A333: Id1297 | B333: 0 | C333: 8457.82 | D333: tier - 2 | E333: R1011 | F333: tier - 2 | G333: tier - 3 | H333: 1972 | I333: {=IF(D333="", INDEX($D$2:$D$2345, MODE(MATCH(IF($D$2:$D$2345<>"",$D$2:$D$2345), IF($D$2:$D$2345<>"",$D$2:$D$2345),0))), D333)} -> tier - 2 | J333: {=IF(G333="", INDEX($G$2:$G$2345, MODE(MATCH(IF($G$2:$G$2345<>"",$G$2:$G$2345), IF($G$2:$G$2345<>"",$G$2:$G$2345),0))), G333)} -> tier - 3 | K333: {=IF(E333="", INDEX($E$2:$E$2345, MODE(MATCH(IF($E$2:$E$2345<>"",$E$2:$E$2345), IF($E$2:$E$2345<>"",$E$2:$E$2345),0))), E333)} -> R1011 | L333: =INT(YEARFRAC(M333,DATE(2023,6,8))) -> 30 | M333: 33964
A334: Id1298 | B334: 3 | C334: 8450.82 | D334: tier - 2 | E334: R1025 | F334: tier - 2 | G334: tier - 2 | H334: 1984 | I334: {=IF(D334="", INDEX($D$2:$D$2345, MODE(MATCH(IF($D$2:$D$2345<>"",$D$2:$D$2345), IF($D$2:$D$2345<>"",$D$2:$D$2345),0))), D334)} -> tier - 2 | J334: {=IF(G334="", INDEX($G$2:$G$2345, MODE(MATCH(IF($G$2:$G$2345<>"",$G$2:$G$2345), IF($G$2:$G$2345<>"",$G$2:$G$2345),0))), G334)} -> tier - 2 | K334: {=IF(E334="", INDEX($E$2:$E$2345, MODE(MATCH(IF($E$2:$E$2345<>"",$E$2:$E$2345), IF($E$2:$E$2345<>"",$E$2:$E$2345),0))), E334)} -> R1025 | L334: =INT(YEARFRAC(M334,DATE(2023,6,8))) -> 50 | M334: 26469
A335: Id1299 | B335: 0 | C335: 8448.66 | D335: tier - 3 | E335: R1013 | F335: tier - 3 | G335: tier - 1 | H335: 1966 | I335: {=IF(D335="", INDEX($D$2:$D$2345, MODE(MATCH(IF($D$2:$D$2345<>"",$D$2:$D$2345), IF($D$2:$D$2345<>"",$D$2:$D$2345),0))), D335)} -> tier - 3 | J335: {=IF(G335="", INDEX($G$2:$G$2345, MODE(MATCH(IF($G$2:$G$2345<>"",$G$2:$G$2345), IF($G$2:$G$2345<>"",$G$2:$G$2345),0))), G335)} -> tier - 1 | K335: {=IF(E335="", INDEX($E$2:$E$2345, MODE(MATCH(IF($E$2:$E$2345<>"",$E$2:$E$2345), IF($E$2:$E$2345<>"",$E$2:$E$2345),0))), E335)} -> R1013 | L335: =INT(YEARFRAC(M335,DATE(2023,6,8))) -> 38 | M335: 30845
A336: Id13 | B336: 0 | C336: 48673.56 | D336: tier - 1 | E336: R1013 | F336: tier - 1 | G336: tier - 2 | H336: 1962 | I336: {=IF(D336="", INDEX($D$2:$D$2345, MODE(MATCH(IF($D$2:$D$2345<>"",$D$2:$D$2345), IF($D$2:$D$2345<>"",$D$2:$D$2345),0))), D336)} -> tier - 1 | J336: {=IF(G336="", INDEX($G$2:$G$2345, MODE(MATCH(IF($G$2:$G$2345<>"",$G$2:$G$2345), IF($G$2:$G$2345<>"",$G$2:$G$2345),0))), G336)} -> tier - 2 | K336: {=IF(E336="", INDEX($E$2:$E$2345, MODE(MATCH(IF($E$2:$E$2345<>"",$E$2:$E$2345), IF($E$2:$E$2345<>"",$E$2:$E$2345),0))), E336)} -> R1013 | L336: =INT(YEARFRAC(M336,DATE(2023,6,8))) -> 57 | M336: 24026
... A780: Id17 | B780: 1 | C780: 47928.03 | D780: tier - 2 | E780: R1011 | F780: tier - 2 | G780: tier - 3 | H780: 1958 | I780: {=IF(D780="", INDEX($D$2:$D$2345, MODE(MATCH(IF($D$2:$D$2345<>"",$D$2:$D$2345), IF($D$2:$D$2345<>"",$D$2:$D$2345),0))), D780)} -> tier - 2 | J780: {=IF(G780="", INDEX($G$2:$G$2345, MODE(MATCH(IF($G$2:$G$2345<>"",$G$2:$G$2345), IF($G$2:$G$2345<>"",$G$2:$G$2345),0))), G780)} -> tier - 3 | K780: {=IF(E780="", INDEX($E$2:$E$2345, MODE(MATCH(IF($E$2:$E$2345<>"",$E$2:$E$2345), IF($E$2:$E$2345<>"",$E$2:$E$2345),0))), E780)} -> R1011 | L780: =INT(YEARFRAC(M780,DATE(2023,6,8))) -> 60 | M780: 22966
A781: Id170 | B781: 1 | C781: 37165.16 | D781: tier - 1 | F781: tier - 1 | G781: tier - 3 | H781: 2000 | I781: {=IF(D781="", INDEX($D$2:$D$2345, MODE(MATCH(IF($D$2:$D$2345<>"",$D$2:$D$2345), IF($D$2:$D$2345<>"",$D$2:$D$2345),0))), D781)} -> tier - 1 | J781: {=IF(G781="", INDEX($G$2:$G$2345, MODE(MATCH(IF($G$2:$G$2345<>"",$G$2:$G$2345), IF($G$2:$G$2345<>"",$G$2:$G$2345),0))), G781)} -> tier - 3 | K781: {=IF(E781="", INDEX($E$2:$E$2345, MODE(MATCH(IF($E$2:$E$2345<>"",$E$2:$E$2345), IF($E$2:$E$2345<>"",$E$2:$E$2345),0))), E781)} -> R1013 | L781: =INT(YEARFRAC(M781,DATE(2023,6,8))) -> 32 | M781: 33121
A782: Id1700 | B782: 2 | C782: 5428.98 | D782: tier - 2 | E782: R1012 | F782: tier - 2 | G782: tier - 2 | H782: 1978 | I782: {=IF(D782="", INDEX($D$2:$D$2345, MODE(MATCH(IF($D$2:$D$2345<>"",$D$2:$D$2345), IF($D$2:$D$2345<>"",$D$2:$D$2345),0))), D782)} -> tier - 2 | J782: {=IF(G782="", INDEX($G$2:$G$2345, MODE(MATCH(IF($G$2:$G$2345<>"",$G$2:$G$2345), IF($G$2:$G$2345<>"",$G$2:$G$2345),0))), G782)} -> tier - 2 | K782: {=IF(E782="", INDEX($E$2:$E$2345, MODE(MATCH(IF($E$2:$E$2345<>"",$E$2:$E$2345), IF($E$2:$E$2345<>"",$E$2:$E$2345),0))), E782)} -> R1012 | L782: =INT(YEARFRAC(M782,DATE(2023,6,8))) -> 41 | M782: 30110
A783: Id1701 | B783: 3 | C783: 5428.73 | D783: tier - 3 | E783: R1017 | F783: tier - 3 | G783: tier - 1 | H783: 1992 | I783: {=IF(D783="", INDEX($D$2:$D$2345, MODE(MATCH(IF($D$2:$D$2345<>"",$D$2:$D$2345), IF($D$2:$D$2345<>"",$D$2:$D$2345),0))), D783)} -> tier - 3 | J783: {=IF(G783="", INDEX($G$2:$G$2345, MODE(MATCH(IF($G$2:$G$2345<>"",$G$2:$G$2345), IF($G$2:$G$2345<>"",$G$2:$G$2345),0))), G783)} -> tier - 1 | K783: {=IF(E783="", INDEX($E$2:$E$2345, MODE(MATCH(IF($E$2:$E$2345<>"",$E$2:$E$2345), IF($E$2:$E$2345<>"",$E$2:$E$2345),0))), E783)} -> R1017 | L783: =INT(YEARFRAC(M783,DATE(2023,6,8))) -> 44 | M783: 28750
A784: Id1702 | B784: 3 | C784: 5425.02 | D784: tier - 2 | E784: R1012 | F784: tier - 2 | G784: tier - 1 | H784: 1991 | I784: {=IF(D784="", INDEX($D$2:$D$2345, MODE(MATCH(IF($D$2:$D$2345<>"",$D$2:$D$2345), IF($D$2:$D$2345<>"",$D$2:$D$2345),0))), D784)} -> tier - 2 | J784: {=IF(G784="", INDEX($G$2:$G$2345, MODE(MATCH(IF($G$2:$G$2345<>"",$G$2:$G$2345), IF($G$2:$G$2345<>"",$G$2:$G$2345),0))), G784)} -> tier - 1 | K784: {=IF(E784="", INDEX($E$2:$E$2345, MODE(MATCH(IF($E$2:$E$2345<>"",$E$2:$E$2345), IF($E$2:$E$2345<>"",$E$2:$E$2345),0))), E784)} -> R1012 | L784: =INT(YEARFRAC(M784,DATE(2023,6,8))) -> 30 | M784: 33791
A785: Id1703 | B785: 0 | C785: 5415.66 | D785: tier - 2 | E785: R1013 | F785: tier - 2 | G785: tier - 3 | H785: 1982 | I785: {=IF(D785="", INDEX($D$2:$D$2345, MODE(MATCH(IF($D$2:$D$2345<>"",$D$2:$D$2345), IF($D$2:$D$2345<>"",$D$2:$D$2345),0))), D785)} -> tier - 2 | J785: {=IF(G785="", INDEX($G$2:$G$2345, MODE(MATCH(IF($G$2:$G$2345<>"",$G$2:$G$2345), IF($G$2:$G$2345<>"",$G$2:$G$2345),0))), G785)} -> tier - 3 | K785: {=IF(E785="", INDEX($E$2:$E$2345, MODE(MATCH(IF($E$2:$E$2345<>"",$E$2:$E$2345), IF($E$2:$E$2345<>"",$E$2:$E$2345),0))), E785)} -> R1013 | L785: =INT(YEARFRAC(M785,DATE(2023,6,8))) -> 31 | M785: 33508
A786: Id1704 | B786: 1 | C786: 5411.99 | D786: tier - 2 | E786: R1012 | F786: tier - 2 | G786: tier - 3 | H786: 1975 | I786: {=IF(D786="", INDEX($D$2:$D$2345, MODE(MATCH(IF($D$2:$D$2345<>"",$D$2:$D$2345), IF($D$2:$D$2345<>"",$D$2:$D$2345),0))), D786)} -> tier - 2 | J786: {=IF(G786="", INDEX($G$2:$G$2345, MODE(MATCH(IF($G$2:$G$2345<>"",$G$2:$G$2345), IF($G$2:$G$2345<>"",$G$2:$G$2345),0))), G786)} -> tier - 3 | K786: {=IF(E786="", INDEX($E$2:$E$2345, MODE(MATCH(IF($E$2:$E$2345<>"",$E$2:$E$2345), IF($E$2:$E$2345<>"",$E$2:$E$2345),0))), E786)} -> R1012 | L786: =INT(YEARFRAC(M786,DATE(2023,6,8))) -> 40 | M786: 30221
A787: Id1705 | B787: 3 | C787: 5402.89 | D787: tier - 2 | E787: R1013 | F787: tier - 2 | G787: tier - 1 | H787: 1985 | I787: {=IF(D787="", INDEX($D$2:$D$2345, MODE(MATCH(IF($D$2:$D$2345<>"",$D$2:$D$2345), IF($D$2:$D$2345<>"",$D$2:$D$2345),0))), D787)} -> tier - 2 | J787: {=IF(G787="", INDEX($G$2:$G$2345, MODE(MATCH(IF($G$2:$G$2345<>"",$G$2:$G$2345), IF($G$2:$G$2345<>"",$G$2:$G$2345),0))), G787)} -> tier - 1 | K787: {=IF(E787="", INDEX($E$2:$E$2345, MODE(MATCH(IF($E$2:$E$2345<>"",$E$2:$E$2345), IF($E$2:$E$2345<>"",$E$2:$E$2345),0))), E787)} -> R1013 | L787: =INT(YEARFRAC(M787,DATE(2023,6,8))) -> 47 | M787: 27751
A788: Id1706 | B788: 0 | C788: 5400.98 | D788: tier - 2 | E788: R1013 | F788: tier - 2 | G788: tier - 2 | H788: 1984 | I788: {=IF(D788="", INDEX($D$2:$D$2345, MODE(MATCH(IF($D$2:$D$2345<>"",$D$2:$D$2345), IF($D$2:$D$2345<>"",$D$2:$D$2345),0))), D788)} -> tier - 2 | J788: {=IF(G788="", INDEX($G$2:$G$2345, MODE(MATCH(IF($G$2:$G$2345<>"",$G$2:$G$2345), IF($G$2:$G$2345<>"",$G$2:$G$2345),0))), G788)} -> tier - 2 | K788: {=IF(E788="", INDEX($E$2:$E$2345, MODE(MATCH(IF($E$2:$E$2345<>"",$E$2:$E$2345), IF($E$2:$E$2345<>"",$E$2:$E$2345),0))), E788)} -> R1013 | L788: =INT(YEARFRAC(M788,DATE(2023,6,8))) -> 37 | M788: 31260
A789: Id1707 | B789: 0 | C789: 5397.62 | D789: tier - 2 | E789: R1013 | F789: tier - 2 | G789: tier - 2 | H789: 1984 | I789: {=IF(D789="", INDEX($D$2:$D$2345, MODE(MATCH(IF($D$2:$D$2345<>"",$D$2:$D$2345), IF($D$2:$D$2345<>"",$D$2:$D$2345),0))), D789)} -> tier - 2 | J789: {=IF(G789="", INDEX($G$2:$G$2345, MODE(MATCH(IF($G$2:$G$2345<>"",$G$2:$G$2345), IF($G$2:$G$2345<>"",$G$2:$G$2345),0))), G789)} -> tier - 2 | K789: {=IF(E789="", INDEX($E$2:$E$2345, MODE(MATCH(IF($E$2:$E$2345<>"",$E$2:$E$2345), IF($E$2:$E$2345<>"",$E$2:$E$2345),0))), E789)} -> R1013 | L789: =INT(YEARFRAC(M789,DATE(2023,6,8))) -> 38 | M789: 30928
...

Sheet MedicHistory
A1: Customer ID | B1: BMI | C1: HBA1C | D1: Heart Issues | E1: Any Transplants | F1: Cancer history | G1: MajorSurgeries | H1: smoker2 | I1: Weight status | J1: Smoker | K1: Diabetic | L1: Diabetics
A2: Id1 | B2: 47.41 | C2: 7.47 | D2: No | E2: No | F2: No | G2: 0 | H2: yes | I2: =IF(Medic_History[[#This Row],[BMI]]>=30,"Obisity",IF(Medic_History[[#This Row],[BMI]]>=25,"over weight",IF(Medic_History[[#This Row],[BMI]]>=18.5,"Normal weight","Under weight"))) -> Obisity | J2: {=IF(H2="", INDEX($H$2:$H$2336, MODE(MATCH(IF($H$2:$H$2336<>"",$H$2:$H$2336), IF($H$2:$H$2336<>"",$H$2:$H$2336),0))), H3)} -> yes | K2: =IF(C2<=5.7,"Normal",IF(C2<=6.2,"prediabetes","Diabetes")) -> Diabetes | L2: =IF(C2<=5.7,"Normal",IF(C2<=6.2,"prediabetes","Diabetes")) -> Diabetes
A3: Id2 | B3: 30.36 | C3: 5.77 | D3: No | E3: No | F3: No | G3: 0 | H3: yes | I3: =IF(Medic_History[[#This Row],[BMI]]>=30,"Obisity",IF(Medic_History[[#This Row],[BMI]]>=25,"over weight",IF(Medic_History[[#This Row],[BMI]]>=18.5,"Normal weight","Under weight"))) -> Obisity | J3: {=IF(H3="", INDEX($H$2:$H$2336, MODE(MATCH(IF($H$2:$H$2336<>"",$H$2:$H$2336), IF($H$2:$H$2336<>"",$H$2:$H$2336),0))), H4)} -> yes | K3: =IF(B3<5.7,"Normal",IF(B3<6.2,"prediabetes","Diabetes")) -> Diabetes | L3: =IF(C3<=5.7,"Normal",IF(C3<=6.2,"prediabetes","Diabetes")) -> prediabetes
A4: Id3 | B4: 34.485 | C4: 11.87 | D4: yes | E4: No | F4: No | G4: 2 | H4: yes | I4: =IF(Medic_History[[#This Row],[BMI]]>=30,"Obisity",IF(Medic_History[[#This Row],[BMI]]>=25,"over weight",IF(Medic_History[[#This Row],[BMI]]>=18.5,"Normal weight","Under weight"))) -> Obisity | J4: {=IF(H4="", INDEX($H$2:$H$2336, MODE(MATCH(IF($H$2:$H$2336<>"",$H$2:$H$2336), IF($H$2:$H$2336<>"",$H$2:$H$2336),0))), H5)} -> yes | K4: =IF(B4<5.7,"Normal",IF(B4<6.2,"prediabetes","Diabetes")) -> Diabetes | L4: =IF(C4<=5.7,"Normal",IF(C4<=6.2,"prediabetes","Diabetes")) -> Diabetes
A5: Id4 | B5: 38.095 | C5: 6.05 | D5: No | E5: No | F5: No | G5: 0 | H5: yes | I5: =IF(Medic_History[[#This Row],[BMI]]>=30,"Obisity",IF(Medic_History[[#This Row],[BMI]]>=25,"over weight",IF(Medic_History[[#This Row],[BMI]]>=18.5,"Normal weight","Under weight"))) -> Obisity | J5: {=IF(H5="", INDEX($H$2:$H$2336, MODE(MATCH(IF($H$2:$H$2336<>"",$H$2:$H$2336), IF($H$2:$H$2336<>"",$H$2:$H$2336),0))), H6)} -> yes | K5: =IF(B5<5.7,"Normal",IF(B5<6.2,"prediabetes","Diabetes")) -> Diabetes | L5: =IF(C5<=5.7,"Normal",IF(C5<=6.2,"prediabetes","Diabetes")) -> prediabetes
A6: Id5 | B6: 35.53 | C6: 5.45 | D6: No | E6: No | F6: No | G6: 0 | H6: yes | I6: =IF(Medic_History[[#This Row],[BMI]]>=30,"Obisity",IF(Medic_History[[#This Row],[BMI]]>=25,"over weight",IF(Medic_History[[#This Row],[BMI]]>=18.5,"Normal weight","Under weight"))) -> Obisity | J6: {=IF(H6="", INDEX($H$2:$H$2336, MODE(MATCH(IF($H$2:$H$2336<>"",$H$2:$H$2336), IF($H$2:$H$2336<>"",$H$2:$H$2336),0))), H7)} -> yes | K6: =IF(B6<5.7,"Normal",IF(B6<6.2,"prediabetes","Diabetes")) -> Diabetes | L6: =IF(C6<=5.7,"Normal",IF(C6<=6.2,"prediabetes","Diabetes")) -> Normal
A7: Id6 | B7: 32.8 | C7: 6.59 | D7: No | E7: No | F7: No | G7: 0 | H7: yes | I7: =IF(Medic_History[[#This Row],[BMI]]>=30,"Obisity",IF(Medic_History[[#This Row],[BMI]]>=25,"over weight",IF(Medic_History[[#This Row],[BMI]]>=18.5,"Normal weight","Under weight"))) -> Obisity | J7: {=IF(H7="", INDEX($H$2:$H$2336, MODE(MATCH(IF($H$2:$H$2336<>"",$H$2:$H$2336), IF($H$2:$H$2336<>"",$H$2:$H$2336),0))), H8)} -> yes | K7: =IF(B7<5.7,"Normal",IF(B7<6.2,"prediabetes","Diabetes")) -> Diabetes | L7: =IF(C7<=5.7,"Normal",IF(C7<=6.2,"prediabetes","Diabetes")) -> Diabetes
A8: Id7 | B8: 36.4 | C8: 6.07 | D8: No | E8: No | F8: No | G8: 0 | H8: yes | I8: =IF(Medic_History[[#This Row],[BMI]]>=30,"Obisity",IF(Medic_History[[#This Row],[BMI]]>=25,"over weight",IF(Medic_History[[#This Row],[BMI]]>=18.5,"Normal weight","Under weight"))) -> Obisity | J8: {=IF(H8="", INDEX($H$2:$H$2336, MODE(MATCH(IF($H$2:$H$2336<>"",$H$2:$H$2336), IF($H$2:$H$2336<>"",$H$2:$H$2336),0))), H9)} -> yes | K8: =IF(B8<5.7,"Normal",IF(B8<6.2,"prediabetes","Diabetes")) -> Diabetes | L8: =IF(C8<=5.7,"Normal",IF(C8<=6.2,"prediabetes","Diabetes")) -> prediabetes
A9: Id8 | B9: 36.96 | C9: 7.93 | D9: No | E9: No | F9: No | G9: 3 | H9: yes | I9: =IF(Medic_History[[#This Row],[BMI]]>=30,"Obisity",IF(Medic_History[[#This Row],[BMI]]>=25,"over weight",IF(Medic_History[[#This Row],[BMI]]>=18.5,"Normal weight","Under weight"))) -> Obisity | J9: {=IF(H9="", INDEX($H$2:$H$2336, MODE(MATCH(IF($H$2:$H$2336<>"",$H$2:$H$2336), IF($H$2:$H$2336<>"",$H$2:$H$2336),0))), H10)} -> yes | K9: =IF(B9<5.7,"Normal",IF(B9<6.2,"prediabetes","Diabetes")) -> Diabetes | L9: =IF(C9<=5.7,"Normal",IF(C9<=6.2,"prediabetes","Diabetes")) -> Diabetes
A10: Id9 | B10: 41.14 | C10: 9.58 | D10: yes | E10: No | F10: Yes | G10: 1 | H10: yes | I10: =IF(Medic_History[[#This Row],[BMI]]>=30,"Obisity",IF(Medic_History[[#This Row],[BMI]]>=25,"over weight",IF(Medic_History[[#This Row],[BMI]]>=18.5,"Normal weight","Under weight"))) -> Obisity | J10: {=IF(H10="", INDEX($H$2:$H$2336, MODE(MATCH(IF($H$2:$H$2336<>"",$H$2:$H$2336), IF($H$2:$H$2336<>"",$H$2:$H$2336),0))), H11)} -> yes | K10: =IF(B10<=5.7,"Normal",IF(B10<=6.2,"prediabetes","Diabetes")) -> Diabetes | L10: =IF(C10<=5.7,"Normal",IF(C10<=6.2,"prediabetes","Diabetes")) -> Diabetes
A11: Id10 | B11: 38.06 | C11: 10.79 | D11: No | E11: No | F11: No | G11: 0 | H11: yes | I11: =IF(Medic_History[[#This Row],[BMI]]>=30,"Obisity",IF(Medic_History[[#This Row],[BMI]]>=25,"over weight",IF(Medic_History[[#This Row],[BMI]]>=18.5,"Normal weight","Under weight"))) -> Obisity | J11: {=IF(H11="", INDEX($H$2:$H$2336, MODE(MATCH(IF($H$2:$H$2336<>"",$H$2:$H$2336), IF($H$2:$H$2336<>"",$H$2:$H$2336),0))), H12)} -> yes | K11: =IF(B11<5.7,"Normal",IF(B11<6.2,"prediabetes","Diabetes")) -> Diabetes | L11: =IF(C11<=5.7,"Normal",IF(C11<=6.2,"prediabetes","Diabetes")) -> Diabetes
A12: Id11 | B12: 37.7 | C12: 5.96 | D12: yes | E12: No | F12: No | G12: 2 | H12: yes | I12: =IF(Medic_History[[#This Row],[BMI]]>=30,"Obisity",IF(Medic_History[[#This Row],[BMI]]>=25,"over weight",IF(Medic_History[[#This Row],[BMI]]>=18.5,"Normal weight","Under weight"))) -> Obisity | J12: {=IF(H12="", INDEX($H$2:$H$2336, MODE(MATCH(IF($H$2:$H$2336<>"",$H$2:$H$2336), IF($H$2:$H$2336<>"",$H$2:$H$2336),0))), H13)} -> yes | K12: =IF(B12<5.7,"Normal",IF(B12<6.2,"prediabetes","Diabetes")) -> Diabetes | L12: =IF(C12<=5.7,"Normal",IF(C12<=6.2,"prediabetes","Diabetes")) -> prediabetes
A13: Id12 | B13: 42.13 | C13: 11.9 | D13: No | E13: No | F13: No | G13: 0 | H13: yes | I13: =IF(Medic_History[[#This Row],[BMI]]>=30,"Obisity",IF(Medic_History[[#This Row],[BMI]]>=25,"over weight",IF(Medic_History[[#This Row],[BMI]]>=18.5,"Normal weight","Under weight"))) -> Obisity | J13: {=IF(H13="", INDEX($H$2:$H$2336, MODE(MATCH(IF($H$2:$H$2336<>"",$H$2:$H$2336), IF($H$2:$H$2336<>"",$H$2:$H$2336),0))), H14)} -> yes | K13: =IF(B13<5.7,"Normal",IF(B13<6.2,"prediabetes","Diabetes")) -> Diabetes | L13: =IF(C13<=5.7,"Normal",IF(C13<=6.2,"prediabetes","Diabetes")) -> Diabetes
A14: Id13 | B14: 40.92 | C14: 8.41 | D14: No | E14: No | F14: No | G14: 0 | H14: yes | I14: =IF(Medic_History[[#This Row],[BMI]]>=30,"Obisity",IF(Medic_History[[#This Row],[BMI]]>=25,"over weight",IF(Medic_History[[#This Row],[BMI]]>=18.5,"Normal weight","Under weight"))) -> Obisity | J14: {=IF(H14="", INDEX($H$2:$H$2336, MODE(MATCH(IF($H$2:$H$2336<>"",$H$2:$H$2336), IF($H$2:$H$2336<>"",$H$2:$H$2336),0))), H15)} -> yes | K14: =IF(B14<5.7,"Normal",IF(B14<6.2,"prediabetes","Diabetes")) -> Diabetes | L14: =IF(C14<=5.7,"Normal",IF(C14<=6.2,"prediabetes","Diabetes")) -> Diabetes
A15: Id14 | B15: 40.565 | C15: 7.02 | D15: No | E15: No | F15: No | G15: 0 | H15: yes | I15: =IF(Medic_History[[#This Row],[BMI]]>=30,"Obisity",IF(Medic_History[[#This Row],[BMI]]>=25,"over weight",IF(Medic_History[[#This Row],[BMI]]>=18.5,"Normal weight","Under weight"))) -> Obisity | J15: {=IF(H15="", INDEX($H$2:$H$2336, MODE(MATCH(IF($H$2:$H$2336<>"",$H$2:$H$2336), IF($H$2:$H$2336<>"",$H$2:$H$2336),0))), H16)} -> yes | K15: =IF(B15<5.7,"Normal",IF(B15<6.2,"prediabetes","Diabetes")) -> Diabetes | L15: =IF(C15<=5.7,"Normal",IF(C15<=6.2,"prediabetes","Diabetes")) -> Diabetes
A16: Id15 | B16: 36.385 | C16: 7.59 | D16: yes | E16: No | F16: No | G16: 2 | H16: yes | I16: =IF(Medic_History[[#This Row],[BMI]]>=30,"Obisity",IF(Medic_History[[#This Row],[BMI]]>=25,"over weight",IF(Medic_History[[#This Row],[BMI]]>=18.5,"Normal weight","Under weight"))) -> Obisity | J16: {=IF(H16="", INDEX($H$2:$H$2336, MODE(MATCH(IF($H$2:$H$2336<>"",$H$2:$H$2336), IF($H$2:$H$2336<>"",$H$2:$H$2336),0))), H17)} -> yes | K16: =IF(B16<5.7,"Normal",IF(B16<6.2,"prediabetes","Diabetes")) -> Diabetes | L16: =IF(C16<=5.7,"Normal",IF(C16<=6.2,"prediabetes","Diabetes")) -> Diabetes
A17: Id16 | B17: 39.9 | C17: 11.32 | D17: No | E17: No | F17: No | G17: 0 | H17: yes | I17: =IF(Medic_History[[#This Row],[BMI]]>=30,"Obisity",IF(Medic_History[[#This Row],[BMI]]>=25,"over weight",IF(Medic_History[[#This Row],[BMI]]>=18.5,"Normal weight","Under weight"))) -> Obisity | J17: {=IF(H17="", INDEX($H$2:$H$2336, MODE(MATCH(IF($H$2:$H$2336<>"",$H$2:$H$2336), IF($H$2:$H$2336<>"",$H$2:$H$2336),0))), H18)} -> yes | K17: =IF(B17<5.7,"Normal",IF(B17<6.2,"prediabetes","Diabetes")) -> Diabetes | L17: =IF(C17<=5.7,"Normal",IF(C17<=6.2,"prediabetes","Diabetes")) -> Diabetes
A18: Id17 | B18: 33.8 | C18: 7.67 | D18: No | E18: No | F18: No | G18: 3 | H18: yes | I18: =IF(Medic_History[[#This Row],[BMI]]>=30,"Obisity",IF(Medic_History[[#This Row],[BMI]]>=25,"over weight",IF(Medic_History[[#This Row],[BMI]]>=18.5,"Normal weight","Under weight"))) -> Obisity | J18: {=IF(H18="", INDEX($H$2:$H$2336, MODE(MATCH(IF($H$2:$H$2336<>"",$H$2:$H$2336), IF($H$2:$H$2336<>"",$H$2:$H$2336),0))), H19)} -> yes | K18: =IF(B18<5.7,"Normal",IF(B18<6.2,"prediabetes","Diabetes")) -> Diabetes | L18: =IF(C18<=5.7,"Normal",IF(C18<=6.2,"prediabetes","Diabetes")) -> Diabetes
A19: Id18 | B19: 36.765 | C19: 7.29 | D19: yes | E19: No | F19: Yes | G19: 1 | H19: yes | I19: =IF(Medic_History[[#This Row],[BMI]]>=30,"Obisity",IF(Medic_History[[#This Row],[BMI]]>=25,"over weight",IF(Medic_History[[#This Row],[BMI]]>=18.5,"Normal weight","Under weight"))) -> Obisity | J19: {=IF(H19="", INDEX($H$2:$H$2336, MODE(MATCH(IF($H$2:$H$2336<>"",$H$2:$H$2336), IF($H$2:$H$2336<>"",$H$2:$H$2336),0))), H20)} -> yes | K19: =IF(B19<5.7,"Normal",IF(B19<6.2,"prediabetes","Diabetes")) -> Diabetes | L19: =IF(C19<=5.7,"Normal",IF(C19<=6.2,"prediabetes","Diabetes")) -> Diabetes
A20: Id19 | B20: 36.955 | C20: 4.72 | D20: yes | E20: No | F20: No | G20: 1 | H20: yes | I20: =IF(Medic_History[[#This Row],[BMI]]>=30,"Obisity",IF(Medic_History[[#This Row],[BMI]]>=25,"over weight",IF(Medic_History[[#This Row],[BMI]]>=18.5,"Normal weight","Under weight"))) -> Obisity | J20: {=IF(H20="", INDEX($H$2:$H$2336, MODE(MATCH(IF($H$2:$H$2336<>"",$H$2:$H$2336), IF($H$2:$H$2336<>"",$H$2:$H$2336),0))), H21)} -> yes | K20: =IF(B20<5.7,"Normal",IF(B20<6.2,"prediabetes","Diabetes")) -> Diabetes | L20: =IF(C20<=5.7,"Normal",IF(C20<=6.2,"prediabetes","Diabetes")) -> Normal
A21: Id20 | B21: 42.9 | C21: 11.41 | D21: No | E21: No | F21: No | G21: 0 | H21: yes | I21: =IF(Medic_History[[#This Row],[BMI]]>=30,"Obisity",IF(Medic_History[[#This Row],[BMI]]>=25,"over weight",IF(Medic_History[[#This Row],[BMI]]>=18.5,"Normal weight","Under weight"))) -> Obisity | J21: {=IF(H21="", INDEX($H$2:$H$2336, MODE(MATCH(IF($H$2:$H$2336<>"",$H$2:$H$2336), IF($H$2:$H$2336<>"",$H$2:$H$2336),0))), H22)} -> yes | K21: =IF(B21<5.7,"Normal",IF(B21<6.2,"prediabetes","Diabetes")) -> Diabetes | L21: =IF(C21<=5.7,"Normal",IF(C21<=6.2,"prediabetes","Diabetes")) -> Diabetes
A22: Id21 | B22: 36.3 | C22: 11.5 | D22: yes | E22: No | F22: No | G22: 2 | H22: yes | I22: =IF(Medic_History[[#This Row],[BMI]]>=30,"Obisity",IF(Medic_History[[#This Row],[BMI]]>=25,"over weight",IF(Medic_History[[#This Row],[BMI]]>=18.5,"Normal weight","Under weight"))) -> Obisity | J22: {=IF(H22="", INDEX($H$2:$H$2336, MODE(MATCH(IF($H$2:$H$2336<>"",$H$2:$H$2336), IF($H$2:$H$2336<>"",$H$2:$H$2336),0))), H23)} -> yes | K22: =IF(B22<5.7,"Normal",IF(B22<6.2,"prediabetes","Diabetes")) -> Diabetes | L22: =IF(C22<=5.7,"Normal",IF(C22<=6.2,"prediabetes","Diabetes")) -> Diabetes
... A2335: Id2334 | B2335: 17.6 | C2335: 4.39 | D2335: No | E2335: No | F2335: No | G2335: 1 | H2335: No | I2335: =IF(Medic_History[[#This Row],[BMI]]>=30,"Obisity",IF(Medic_History[[#This Row],[BMI]]>=25,"over weight",IF(Medic_History[[#This Row],[BMI]]>=18.5,"Normal weight","Under weight"))) -> Under weight | J2335: {=IF(H2335="", INDEX($H$2:$H$2336, MODE(MATCH(IF($H$2:$H$2336<>"",$H$2:$H$2336), IF($H$2:$H$2336<>"",$H$2:$H$2336),0))), H2336)} -> No | K2335: =IF(B2335<5.7,"Normal",IF(B2335<6.2,"prediabetes","Diabetes")) -> Diabetes | L2335: =IF(C2335<=5.7,"Normal",IF(C2335<=6.2,"prediabetes","Diabetes")) -> Normal
A2336: Id2335 | B2336: 17.58 | C2336: 4.51 | D2336: No | E2336: No | F2336: No | G2336: 1 | H2336: No | I2336: =IF(Medic_History[[#This Row],[BMI]]>=30,"Obisity",IF(Medic_History[[#This Row],[BMI]]>=25,"over weight",IF(Medic_History[[#This Row],[BMI]]>=18.5,"Normal weight","Under weight"))) -> Under weight | J2336: {=IF(H2336="", INDEX($H$2:$H$2336, MODE(MATCH(IF($H$2:$H$2336<>"",$H$2:$H$2336), IF($H$2:$H$2336<>"",$H$2:$H$2336),0))), H2337)} -> 0 | L2336: =IF(C2336<=5.7,"Normal",IF(C2336<=6.2,"prediabetes","Diabetes")) -> Normal

Sheet Healthcare (3)
A1: Customer ID | B1: First | C1: BMI | D1: HBA1C | E1: Heart Issues | F1: Any Transplants | G1: Cancer history | H1: MajorSurgeries | I1: smoker2 | J1: Diabetics | K1: Weight status | L1: charges | M1: Hsp Tier | N1: Cty Tier | O1: StateID | P1: Age | Q1: Date of Birth
A2: Id1 | B2: {=_xlfn.XLOOKUP(A2,[1]Customer!A:A,[1]Customer!C:C,"")} -> Kelly | C2: {=_xlfn.XLOOKUP($A2,[1]MedicHistory!A:A,[1]MedicHistory!B:B,"")} -> 47.41 | D2: =_xlfn.XLOOKUP($A2,[1]MedicHistory!A:A,[1]MedicHistory!C:C,"") -> 7.47 | E2: =_xlfn.XLOOKUP($A2,[1]MedicHistory!A:A,[1]MedicHistory!D:D,"") -> No | F2: =_xlfn.XLOOKUP($A2,[1]MedicHistory!A:A,[1]MedicHistory!E:E,"") -> No | G2: =_xlfn.XLOOKUP($A2,[1]MedicHistory!A:A,[1]MedicHistory!F:F,"") -> No | H2: =_xlfn.XLOOKUP($A2,[1]MedicHistory!A:A,[1]MedicHistory!G:G,"") -> 0 | I2: =_xlfn.XLOOKUP($A2,[1]MedicHistory!A:A,[1]MedicHistory!H:H,"") -> yes | J2: Diabetic | K2: =_xlfn.XLOOKUP($A2,[1]MedicHistory!A:A,[1]MedicHistory!I:I,"") -> Obisity | L2: =_xlfn.XLOOKUP($A2,[1]Hospitalisation!A:A,[1]Hospitalisation!C:C,"") -> 63770.43 | M2: =_xlfn.XLOOKUP($A2,[1]Hospitalisation!A:A,[1]Hospitalisation!I:I,"") -> tier - 1 | N2: =_xlfn.XLOOKUP($A2,[1]Hospitalisation!A:A,[1]Hospitalisation!J:J,"") -> tier - 3 | O2: =_xlfn.XLOOKUP($A2,[1]Hospitalisation!A:A,[1]Hospitalisation!K:K,"") -> R1013 | P2: =_xlfn.XLOOKUP($A2,[1]Hospitalisation!A:A,[1]Hospitalisation!L:L,"") -> 39 | Q2: =_xlfn.XLOOKUP($A2,[1]Hospitalisation!A:A,[1]Hospitalisation!M:M,"") -> 30601
A3: Id2 | B3: =_xlfn.XLOOKUP(A3,[1]Customer!A:A,[1]Customer!C:C,"") -> Matthew | C3: {=_xlfn.XLOOKUP($A3,[1]MedicHistory!A:A,[1]MedicHistory!B:B,"")} -> 30.36 | D3: {=_xlfn.XLOOKUP($A3,[1]MedicHistory!A:A,[1]MedicHistory!C:C,"")} -> 5.77 | E3: =_xlfn.XLOOKUP($A3,[1]MedicHistory!A:A,[1]MedicHistory!D:D,"") -> No | F3: =_xlfn.XLOOKUP($A3,[1]MedicHistory!A:A,[1]MedicHistory!E:E,"") -> No | G3: =_xlfn.XLOOKUP($A3,[1]MedicHistory!A:A,[1]MedicHistory!F:F,"") -> No | H3: =_xlfn.XLOOKUP($A3,[1]MedicHistory!A:A,[1]MedicHistory!G:G,"") -> 0 | I3: =_xlfn.XLOOKUP($A3,[1]MedicHistory!A:A,[1]MedicHistory!H:H,"") -> yes | J3: =_xlfn.XLOOKUP($A3,[1]MedicHistory!A:A,[1]MedicHistory!K:K,"") -> Prediabetic | K3: =_xlfn.XLOOKUP($A3,[1]MedicHistory!A:A,[1]MedicHistory!I:I,"") -> Obisity | L3: =_xlfn.XLOOKUP($A3,[1]Hospitalisation!A:A,[1]Hospitalisation!C:C,"") -> 62592.87 | M3: =_xlfn.XLOOKUP($A3,[1]Hospitalisation!A:A,[1]Hospitalisation!I:I,"") -> tier - 2 | N3: =_xlfn.XLOOKUP($A3,[1]Hospitalisation!A:A,[1]Hospitalisation!J:J,"") -> tier - 3 | O3: =_xlfn.XLOOKUP($A3,[1]Hospitalisation!A:A,[1]Hospitalisation!K:K,"") -> R1013 | P3: =_xlfn.XLOOKUP($A3,[1]Hospitalisation!A:A,[1]Hospitalisation!L:L,"") -> 55 | Q3: =_xlfn.XLOOKUP($A3,[1]Hospitalisation!A:A,[1]Hospitalisation!M:M,"") -> 24997
A4: Id3 | B4: =_xlfn.XLOOKUP(A4,[1]Customer!A:A,[1]Customer!C:C,"") -> Phil | C4: {=_xlfn.XLOOKUP($A4,[1]MedicHistory!A:A,[1]MedicHistory!B:B,"")} -> 34.485 | D4: {=_xlfn.XLOOKUP($A4,[1]MedicHistory!A:A,[1]MedicHistory!C:C,"")} -> 11.87 | E4: =_xlfn.XLOOKUP($A4,[1]MedicHistory!A:A,[1]MedicHistory!D:D,"") -> yes | F4: =_xlfn.XLOOKUP($A4,[1]MedicHistory!A:A,[1]MedicHistory!E:E,"") -> No | G4: =_xlfn.XLOOKUP($A4,[1]MedicHistory!A:A,[1]MedicHistory!F:F,"") -> No | H4: =_xlfn.XLOOKUP($A4,[1]MedicHistory!A:A,[1]MedicHistory!G:G,"") -> 2 | I4: =_xlfn.XLOOKUP($A4,[1]MedicHistory!A:A,[1]MedicHistory!H:H,"") -> yes | J4: =_xlfn.XLOOKUP($A4,[1]MedicHistory!A:A,[1]MedicHistory!K:K,"") -> Diabetic | K4: =_xlfn.XLOOKUP($A4,[1]MedicHistory!A:A,[1]MedicHistory!I:I,"") -> Obisity | L4: =_xlfn.XLOOKUP($A4,[1]Hospitalisation!A:A,[1]Hospitalisation!C:C,"") -> 60021.4 | M4: =_xlfn.XLOOKUP($A4,[1]Hospitalisation!A:A,[1]Hospitalisation!I:I,"") -> tier - 1 | N4: =_xlfn.XLOOKUP($A4,[1]Hospitalisation!A:A,[1]Hospitalisation!J:J,"") -> tier - 1 | O4: =_xlfn.XLOOKUP($A4,[1]Hospitalisation!A:A,[1]Hospitalisation!K:K,"") -> R1012 | P4: =_xlfn.XLOOKUP($A4,[1]Hospitalisation!A:A,[1]Hospitalisation!L:L,"") -> 45 | Q4: =_xlfn.XLOOKUP($A4,[1]Hospitalisation!A:A,[1]Hospitalisation!M:M,"") -> 28379
A5: Id4 | B5: =_xlfn.XLOOKUP(A5,[1]Customer!A:A,[1]Customer!C:C,"") -> Kelsey | C5: {=_xlfn.XLOOKUP($A5,[1]MedicHistory!A:A,[1]MedicHistory!B:B,"")} -> 38.095 | D5: {=_xlfn.XLOOKUP($A5,[1]MedicHistory!A:A,[1]MedicHistory!C:C,"")} -> 6.05 | E5: =_xlfn.XLOOKUP($A5,[1]MedicHistory!A:A,[1]MedicHistory!D:D,"") -> No | F5: =_xlfn.XLOOKUP($A5,[1]MedicHistory!A:A,[1]MedicHistory!E:E,"") -> No | G5: =_xlfn.XLOOKUP($A5,[1]MedicHistory!A:A,[1]MedicHistory!F:F,"") -> No | H5: =_xlfn.XLOOKUP($A5,[1]MedicHistory!A:A,[1]MedicHistory!G:G,"") -> 0 | I5: =_xlfn.XLOOKUP($A5,[1]MedicHistory!A:A,[1]MedicHistory!H:H,"") -> yes | J5: =_xlfn.XLOOKUP($A5,[1]MedicHistory!A:A,[1]MedicHistory!K:K,"") -> Prediabetic | K5: =_xlfn.XLOOKUP($A5,[1]MedicHistory!A:A,[1]MedicHistory!I:I,"") -> Obisity | L5: =_xlfn.XLOOKUP($A5,[1]Hospitalisation!A:A,[1]Hospitalisation!C:C,"") -> 58571.07 | M5: =_xlfn.XLOOKUP($A5,[1]Hospitalisation!A:A,[1]Hospitalisation!I:I,"") -> tier - 1 | N5: =_xlfn.XLOOKUP($A5,[1]Hospitalisation!A:A,[1]Hospitalisation!J:J,"") -> tier - 3 | O5: =_xlfn.XLOOKUP($A5,[1]Hospitalisation!A:A,[1]Hospitalisation!K:K,"") -> R1024 | P5: =_xlfn.XLOOKUP($A5,[1]Hospitalisation!A:A,[1]Hospitalisation!L:L,"") -> 53 | Q5: =_xlfn.XLOOKUP($A5,[1]Hospitalisation!A:A,[1]Hospitalisation!M:M,"") -> 25725
A6: Id5 | B6: =_xlfn.XLOOKUP(A6,[1]Customer!A:A,[1]Customer!C:C,"") -> Kristyn | C6: {=_xlfn.XLOOKUP($A6,[1]MedicHistory!A:A,[1]MedicHistory!B:B,"")} -> 35.53 | D6: {=_xlfn.XLOOKUP($A6,[1]MedicHistory!A:A,[1]MedicHistory!C:C,"")} -> 5.45 | E6: =_xlfn.XLOOKUP($A6,[1]MedicHistory!A:A,[1]MedicHistory!D:D,"") -> No | F6: =_xlfn.XLOOKUP($A6,[1]MedicHistory!A:A,[1]MedicHistory!E:E,"") -> No | G6: =_xlfn.XLOOKUP($A6,[1]MedicHistory!A:A,[1]MedicHistory!F:F,"") -> No | H6: =_xlfn.XLOOKUP($A6,[1]MedicHistory!A:A,[1]MedicHistory!G:G,"") -> 0 | I6: =_xlfn.XLOOKUP($A6,[1]MedicHistory!A:A,[1]MedicHistory!H:H,"") -> yes | J6: =_xlfn.XLOOKUP($A6,[1]MedicHistory!A:A,[1]MedicHistory!K:K,"") -> Normal | K6: =_xlfn.XLOOKUP($A6,[1]MedicHistory!A:A,[1]MedicHistory!I:I,"") -> Obisity | L6: =_xlfn.XLOOKUP($A6,[1]Hospitalisation!A:A,[1]Hospitalisation!C:C,"") -> 55135.4 | M6: =_xlfn.XLOOKUP($A6,[1]Hospitalisation!A:A,[1]Hospitalisation!I:I,"") -> tier - 1 | N6: =_xlfn.XLOOKUP($A6,[1]Hospitalisation!A:A,[1]Hospitalisation!J:J,"") -> tier - 2 | O6: =_xlfn.XLOOKUP($A6,[1]Hospitalisation!A:A,[1]Hospitalisation!K:K,"") -> R1012 | P6: =_xlfn.XLOOKUP($A6,[1]Hospitalisation!A:A,[1]Hospitalisation!L:L,"") -> 31 | Q6: =_xlfn.XLOOKUP($A6,[1]Hospitalisation!A:A,[1]Hospitalisation!M:M,"") -> 33408
A7: Id6 | B7: =_xlfn.XLOOKUP(A7,[1]Customer!A:A,[1]Customer!C:C,"") -> Russell | C7: {=_xlfn.XLOOKUP($A7,[1]MedicHistory!A:A,[1]MedicHistory!B:B,"")} -> 32.8 | D7: {=_xlfn.XLOOKUP($A7,[1]MedicHistory!A:A,[1]MedicHistory!C:C,"")} -> 6.59 | E7: =_xlfn.XLOOKUP($A7,[1]MedicHistory!A:A,[1]MedicHistory!D:D,"") -> No | F7: =_xlfn.XLOOKUP($A7,[1]MedicHistory!A:A,[1]MedicHistory!E:E,"") -> No | G7: =_xlfn.XLOOKUP($A7,[1]MedicHistory!A:A,[1]MedicHistory!F:F,"") -> No | H7: =_xlfn.XLOOKUP($A7,[1]MedicHistory!A:A,[1]MedicHistory!G:G,"") -> 0 | I7: =_xlfn.XLOOKUP($A7,[1]MedicHistory!A:A,[1]MedicHistory!H:H,"") -> yes | J7: =_xlfn.XLOOKUP($A7,[1]MedicHistory!A:A,[1]MedicHistory!K:K,"") -> Diabetic | K7: =_xlfn.XLOOKUP($A7,[1]MedicHistory!A:A,[1]MedicHistory!I:I,"") -> Obisity | L7: =_xlfn.XLOOKUP($A7,[1]Hospitalisation!A:A,[1]Hospitalisation!C:C,"") -> 52590.83 | M7: =_xlfn.XLOOKUP($A7,[1]Hospitalisation!A:A,[1]Hospitalisation!I:I,"") -> tier - 1 | N7: =_xlfn.XLOOKUP($A7,[1]Hospitalisation!A:A,[1]Hospitalisation!J:J,"") -> tier - 3 | O7: =_xlfn.XLOOKUP($A7,[1]Hospitalisation!A:A,[1]Hospitalisation!K:K,"") -> R1011 | P7: =_xlfn.XLOOKUP($A7,[1]Hospitalisation!A:A,[1]Hospitalisation!L:L,"") -> 33 | Q7: =_xlfn.XLOOKUP($A7,[1]Hospitalisation!A:A,[1]Hospitalisation!M:M,"") -> 32724
A8: Id7 | B8: =_xlfn.XLOOKUP(A8,[1]Customer!A:A,[1]Customer!C:C,"") -> Scott | C8: {=_xlfn.XLOOKUP($A8,[1]MedicHistory!A:A,[1]MedicHistory!B:B,"")} -> 36.4 | D8: {=_xlfn.XLOOKUP($A8,[1]MedicHistory!A:A,[1]MedicHistory!C:C,"")} -> 6.07 | E8: =_xlfn.XLOOKUP($A8,[1]MedicHistory!A:A,[1]MedicHistory!D:D,"") -> No | F8: =_xlfn.XLOOKUP($A8,[1]MedicHistory!A:A,[1]MedicHistory!E:E,"") -> No | G8: =_xlfn.XLOOKUP($A8,[1]MedicHistory!A:A,[1]MedicHistory!F:F,"") -> No | H8: =_xlfn.XLOOKUP($A8,[1]MedicHistory!A:A,[1]MedicHistory!G:G,"") -> 0 | I8: =_xlfn.XLOOKUP($A8,[1]MedicHistory!A:A,[1]MedicHistory!H:H,"") -> yes | J8: =_xlfn.XLOOKUP($A8,[1]MedicHistory!A:A,[1]MedicHistory!K:K,"") -> Prediabetic | K8: =_xlfn.XLOOKUP($A8,[1]MedicHistory!A:A,[1]MedicHistory!I:I,"") -> Obisity | L8: =_xlfn.XLOOKUP($A8,[1]Hospitalisation!A:A,[1]Hospitalisation!C:C,"") -> 51194.56 | M8: =_xlfn.XLOOKUP($A8,[1]Hospitalisation!A:A,[1]Hospitalisation!I:I,"") -> tier - 1 | N8: =_xlfn.XLOOKUP($A8,[1]Hospitalisation!A:A,[1]Hospitalisation!J:J,"") -> tier - 3 | O8: =_xlfn.XLOOKUP($A8,[1]Hospitalisation!A:A,[1]Hospitalisation!K:K,"") -> R1011 | P8: =_xlfn.XLOOKUP($A8,[1]Hospitalisation!A:A,[1]Hospitalisation!L:L,"") -> 60 | Q8: =_xlfn.XLOOKUP($A8,[1]Hospitalisation!A:A,[1]Hospitalisation!M:M,"") -> 22946
A9: Id8 | B9: =_xlfn.XLOOKUP(A9,[1]Customer!A:A,[1]Customer!C:C,"") -> Stephen | C9: {=_xlfn.XLOOKUP($A9,[1]MedicHistory!A:A,[1]MedicHistory!B:B,"")} -> 36.96 | D9: {=_xlfn.XLOOKUP($A9,[1]MedicHistory!A:A,[1]MedicHistory!C:C,"")} -> 7.93 | E9: =_xlfn.XLOOKUP($A9,[1]MedicHistory!A:A,[1]MedicHistory!D:D,"") -> No | F9: =_xlfn.XLOOKUP($A9,[1]MedicHistory!A:A,[1]MedicHistory!E:E,"") -> No | G9: =_xlfn.XLOOKUP($A9,[1]MedicHistory!A:A,[1]MedicHistory!F:F,"") -> No | H9: =_xlfn.XLOOKUP($A9,[1]MedicHistory!A:A,[1]MedicHistory!G:G,"") -> 3 | I9: =_xlfn.XLOOKUP($A9,[1]MedicHistory!A:A,[1]MedicHistory!H:H,"") -> yes | J9: =_xlfn.XLOOKUP($A9,[1]MedicHistory!A:A,[1]MedicHistory!K:K,"") -> Diabetic | K9: =_xlfn.XLOOKUP($A9,[1]MedicHistory!A:A,[1]MedicHistory!I:I,"") -> Obisity | L9: =_xlfn.XLOOKUP($A9,[1]Hospitalisation!A:A,[1]Hospitalisation!C:C,"") -> 49577.66 | M9: =_xlfn.XLOOKUP($A9,[1]Hospitalisation!A:A,[1]Hospitalisation!I:I,"") -> tier - 2 | N9: =_xlfn.XLOOKUP($A9,[1]Hospitalisation!A:A,[1]Hospitalisation!J:J,"") -> tier - 2 | O9: =_xlfn.XLOOKUP($A9,[1]Hospitalisation!A:A,[1]Hospitalisation!K:K,"") -> R1013 | P9: =_xlfn.XLOOKUP($A9,[1]Hospitalisation!A:A,[1]Hospitalisation!L:L,"") -> 28 | Q9: =_xlfn.XLOOKUP($A9,[1]Hospitalisation!A:A,[1]Hospitalisation!M:M,"") -> 34512
A10: Id9 | B10: =_xlfn.XLOOKUP(A10,[1]Customer!A:A,[1]Customer!C:C,"") -> Patrick | C10: {=_xlfn.XLOOKUP($A10,[1]MedicHistory!A:A,[1]MedicHistory!B:B,"")} -> 41.14 | D10: {=_xlfn.XLOOKUP($A10,[1]MedicHistory!A:A,[1]MedicHistory!C:C,"")} -> 9.58 | E10: =_xlfn.XLOOKUP($A10,[1]MedicHistory!A:A,[1]MedicHistory!D:D,"") -> yes | F10: =_xlfn.XLOOKUP($A10,[1]MedicHistory!A:A,[1]MedicHistory!E:E,"") -> No | G10: =_xlfn.XLOOKUP($A10,[1]MedicHistory!A:A,[1]MedicHistory!F:F,"") -> Yes | H10: =_xlfn.XLOOKUP($A10,[1]MedicHistory!A:A,[1]MedicHistory!G:G,"") -> 1 | I10: =_xlfn.XLOOKUP($A10,[1]MedicHistory!A:A,[1]MedicHistory!H:H,"") -> yes | J10: =_xlfn.XLOOKUP($A10,[1]MedicHistory!A:A,[1]MedicHistory!K:K,"") -> Diabetic | K10: =_xlfn.XLOOKUP($A10,[1]MedicHistory!A:A,[1]MedicHistory!I:I,"") -> Obisity | L10: =_xlfn.XLOOKUP($A10,[1]Hospitalisation!A:A,[1]Hospitalisation!C:C,"") -> 48970.25 | M10: =_xlfn.XLOOKUP($A10,[1]Hospitalisation!A:A,[1]Hospitalisation!I:I,"") -> tier - 1 | N10: =_xlfn.XLOOKUP($A10,[1]Hospitalisation!A:A,[1]Hospitalisation!J:J,"") -> tier - 2 | O10: =_xlfn.XLOOKUP($A10,[1]Hospitalisation!A:A,[1]Hospitalisation!K:K,"") -> R1013 | P10: =_xlfn.XLOOKUP($A10,[1]Hospitalisation!A:A,[1]Hospitalisation!L:L,"") -> 64 | Q10: =_xlfn.XLOOKUP($A10,[1]Hospitalisation!A:A,[1]Hospitalisation!M:M,"") -> 21432
A11: Id10 | B11: =_xlfn.XLOOKUP(A11,[1]Customer!A:A,[1]Customer!C:C,"") -> Brooke | C11: {=_xlfn.XLOOKUP($A11,[1]MedicHistory!A:A,[1]MedicHistory!B:B,"")} -> 38.06 | D11: {=_xlfn.XLOOKUP($A11,[1]MedicHistory!A:A,[1]MedicHistory!C:C,"")} -> 10.79 | E11: =_xlfn.XLOOKUP($A11,[1]MedicHistory!A:A,[1]MedicHistory!D:D,"") -> No | F11: =_xlfn.XLOOKUP($A11,[1]MedicHistory!A:A,[1]MedicHistory!E:E,"") -> No | G11: =_xlfn.XLOOKUP($A11,[1]MedicHistory!A:A,[1]MedicHistory!F:F,"") -> No | H11: =_xlfn.XLOOKUP($A11,[1]MedicHistory!A:A,[1]MedicHistory!G:G,"") -> 0 | I11: =_xlfn.XLOOKUP($A11,[1]MedicHistory!A:A,[1]MedicHistory!H:H,"") -> yes | J11: =_xlfn.XLOOKUP($A11,[1]MedicHistory!A:A,[1]MedicHistory!K:K,"") -> Diabetic | K11: =_xlfn.XLOOKUP($A11,[1]MedicHistory!A:A,[1]MedicHistory!I:I,"") -> Obisity | L11: =_xlfn.XLOOKUP($A11,[1]Hospitalisation!A:A,[1]Hospitalisation!C:C,"") -> 48885.14 | M11: =_xlfn.XLOOKUP($A11,[1]Hospitalisation!A:A,[1]Hospitalisation!I:I,"") -> tier - 1 | N11: =_xlfn.XLOOKUP($A11,[1]Hospitalisation!A:A,[1]Hospitalisation!J:J,"") -> tier - 2 | O11: =_xlfn.XLOOKUP($A11,[1]Hospitalisation!A:A,[1]Hospitalisation!K:K,"") -> R1013 | P11: =_xlfn.XLOOKUP($A11,[1]Hospitalisation!A:A,[1]Hospitalisation!L:L,"") -> 59 | Q11: =_xlfn.XLOOKUP($A11,[1]Hospitalisation!A:A,[1]Hospitalisation!M:M,"") -> 23374
A12: Id11 | B12: =_xlfn.XLOOKUP(A12,[1]Customer!A:A,[1]Customer!C:C,"") -> Andrea Paola | C12: {=_xlfn.XLOOKUP($A12,[1]MedicHistory!A:A,[1]MedicHistory!B:B,"")} -> 37.7 | D12: {=_xlfn.XLOOKUP($A12,[1]MedicHistory!A:A,[1]MedicHistory!C:C,"")} -> 5.96 | E12: =_xlfn.XLOOKUP($A12,[1]MedicHistory!A:A,[1]MedicHistory!D:D,"") -> yes | F12: =_xlfn.XLOOKUP($A12,[1]MedicHistory!A:A,[1]MedicHistory!E:E,"") -> No | G12: =_xlfn.XLOOKUP($A12,[1]MedicHistory!A:A,[1]MedicHistory!F:F,"") -> No | H12: =_xlfn.XLOOKUP($A12,[1]MedicHistory!A:A,[1]MedicHistory!G:G,"") -> 2 | I12: =_xlfn.XLOOKUP($A12,[1]MedicHistory!A:A,[1]MedicHistory!H:H,"") -> yes | J12: =_xlfn.XLOOKUP($A12,[1]MedicHistory!A:A,[1]MedicHistory!K:K,"") -> Prediabetic | K12: =_xlfn.XLOOKUP($A12,[1]MedicHistory!A:A,[1]MedicHistory!I:I,"") -> Obisity | L12: =_xlfn.XLOOKUP($A12,[1]Hospitalisation!A:A,[1]Hospitalisation!C:C,"") -> 48824.45 | M12: =_xlfn.XLOOKUP($A12,[1]Hospitalisation!A:A,[1]Hospitalisation!I:I,"") -> tier - 2 | N12: =_xlfn.XLOOKUP($A12,[1]Hospitalisation!A:A,[1]Hospitalisation!J:J,"") -> tier - 1 | O12: =_xlfn.XLOOKUP($A12,[1]Hospitalisation!A:A,[1]Hospitalisation!K:K,"") -> R1011 | P12: =_xlfn.XLOOKUP($A12,[1]Hospitalisation!A:A,[1]Hospitalisation!L:L,"") -> 44 | Q12: =_xlfn.XLOOKUP($A12,[1]Hospitalisation!A:A,[1]Hospitalisation!M:M,"") -> 28693
A13: Id12 | B13: =_xlfn.XLOOKUP(A13,[1]Customer!A:A,[1]Customer!C:C,"") -> David | C13: {=_xlfn.XLOOKUP($A13,[1]MedicHistory!A:A,[1]MedicHistory!B:B,"")} -> 42.13 | D13: {=_xlfn.XLOOKUP($A13,[1]MedicHistory!A:A,[1]MedicHistory!C:C,"")} -> 11.9 | E13: =_xlfn.XLOOKUP($A13,[1]MedicHistory!A:A,[1]MedicHistory!D:D,"") -> No | F13: =_xlfn.XLOOKUP($A13,[1]MedicHistory!A:A,[1]MedicHistory!E:E,"") -> No | G13: =_xlfn.XLOOKUP($A13,[1]MedicHistory!A:A,[1]MedicHistory!F:F,"") -> No | H13: =_xlfn.XLOOKUP($A13,[1]MedicHistory!A:A,[1]MedicHistory!G:G,"") -> 0 | I13: =_xlfn.XLOOKUP($A13,[1]MedicHistory!A:A,[1]MedicHistory!H:H,"") -> yes | J13: =_xlfn.XLOOKUP($A13,[1]MedicHistory!A:A,[1]MedicHistory!K:K,"") -> Diabetic | K13: =_xlfn.XLOOKUP($A13,[1]MedicHistory!A:A,[1]MedicHistory!I:I,"") -> Obisity | L13: =_xlfn.XLOOKUP($A13,[1]Hospitalisation!A:A,[1]Hospitalisation!C:C,"") -> 48675.52 | M13: =_xlfn.XLOOKUP($A13,[1]Hospitalisation!A:A,[1]Hospitalisation!I:I,"") -> tier - 1 | N13: =_xlfn.XLOOKUP($A13,[1]Hospitalisation!A:A,[1]Hospitalisation!J:J,"") -> tier - 2 | O13: =_xlfn.XLOOKUP($A13,[1]Hospitalisation!A:A,[1]Hospitalisation!K:K,"") -> R1013 | P13: =_xlfn.XLOOKUP($A13,[1]Hospitalisation!A:A,[1]Hospitalisation!L:L,"") -> 63 | Q13: =_xlfn.XLOOKUP($A13,[1]Hospitalisation!A:A,[1]Hospitalisation!M:M,"") -> 21850
A14: Id13 | B14: =_xlfn.XLOOKUP(A14,[1]Customer!A:A,[1]Customer!C:C,"") -> Wade | C14: {=_xlfn.XLOOKUP($A14,[1]MedicHistory!A:A,[1]MedicHistory!B:B,"")} -> 40.92 | D14: {=_xlfn.XLOOKUP($A14,[1]MedicHistory!A:A,[1]MedicHistory!C:C,"")} -> 8.41 | E14: =_xlfn.XLOOKUP($A14,[1]MedicHistory!A:A,[1]MedicHistory!D:D,"") -> No | F14: =_xlfn.XLOOKUP($A14,[1]MedicHistory!A:A,[1]MedicHistory!E:E,"") -> No | G14: =_xlfn.XLOOKUP($A14,[1]MedicHistory!A:A,[1]MedicHistory!F:F,"") -> No | H14: =_xlfn.XLOOKUP($A14,[1]MedicHistory!A:A,[1]MedicHistory!G:G,"") -> 0 | I14: =_xlfn.XLOOKUP($A14,[1]MedicHistory!A:A,[1]MedicHistory!H:H,"") -> yes | J14: =_xlfn.XLOOKUP($A14,[1]MedicHistory!A:A,[1]MedicHistory!K:K,"") -> Diabetic | K14: =_xlfn.XLOOKUP($A14,[1]MedicHistory!A:A,[1]MedicHistory!I:I,"") -> Obisity | L14: =_xlfn.XLOOKUP($A14,[1]Hospitalisation!A:A,[1]Hospitalisation!C:C,"") -> 48673.56 | M14: =_xlfn.XLOOKUP($A14,[1]Hospitalisation!A:A,[1]Hospitalisation!I:I,"") -> tier - 1 | N14: =_xlfn.XLOOKUP($A14,[1]Hospitalisation!A:A,[1]Hospitalisation!J:J,"") -> tier - 2 | O14: =_xlfn.XLOOKUP($A14,[1]Hospitalisation!A:A,[1]Hospitalisation!K:K,"") -> R1013 | P14: =_xlfn.XLOOKUP($A14,[1]Hospitalisation!A:A,[1]Hospitalisation!L:L,"") -> 57 | Q14: =_xlfn.XLOOKUP($A14,[1]Hospitalisation!A:A,[1]Hospitalisation!M:M,"") -> 24026
... A21: Id20 | B21: =_xlfn.XLOOKUP(A21,[1]Customer!A:A,[1]Customer!C:C,"") -> John | C21: {=_xlfn.XLOOKUP($A21,[1]MedicHistory!A:A,[1]MedicHistory!B:B,"")} -> 42.9 | D21: {=_xlfn.XLOOKUP($A21,[1]MedicHistory!A:A,[1]MedicHistory!C:C,"")} -> 11.41 | E21: =_xlfn.XLOOKUP($A21,[1]MedicHistory!A:A,[1]MedicHistory!D:D,"") -> No | F21: =_xlfn.XLOOKUP($A21,[1]MedicHistory!A:A,[1]MedicHistory!E:E,"") -> No | G21: =_xlfn.XLOOKUP($A21,[1]MedicHistory!A:A,[1]MedicHistory!F:F,"") -> No | H21: =_xlfn.XLOOKUP($A21,[1]MedicHistory!A:A,[1]MedicHistory!G:G,"") -> 0 | I21: =_xlfn.XLOOKUP($A21,[1]MedicHistory!A:A,[1]MedicHistory!H:H,"") -> yes | J21: =_xlfn.XLOOKUP($A21,[1]MedicHistory!A:A,[1]MedicHistory!K:K,"") -> Diabetic | K21: =_xlfn.XLOOKUP($A21,[1]MedicHistory!A:A,[1]MedicHistory!I:I,"") -> Obisity | L21: =_xlfn.XLOOKUP($A21,[1]Hospitalisation!A:A,[1]Hospitalisation!C:C,"") -> 47462.89 | M21: =_xlfn.XLOOKUP($A21,[1]Hospitalisation!A:A,[1]Hospitalisation!I:I,"") -> tier - 1 | N21: =_xlfn.XLOOKUP($A21,[1]Hospitalisation!A:A,[1]Hospitalisation!J:J,"") -> tier - 2 | O21: =_xlfn.XLOOKUP($A21,[1]Hospitalisation!A:A,[1]Hospitalisation!K:K,"") -> R1013 | P21: =_xlfn.XLOOKUP($A21,[1]Hospitalisation!A:A,[1]Hospitalisation!L:L,"") -> 58 | Q21: =_xlfn.XLOOKUP($A21,[1]Hospitalisation!A:A,[1]Hospitalisation!M:M,"") -> 23647
A22: Id21 | B22: =_xlfn.XLOOKUP(A22,[1]Customer!A:A,[1]Customer!C:C,"") -> Myles | C22: {=_xlfn.XLOOKUP($A22,[1]MedicHistory!A:A,[1]MedicHistory!B:B,"")} -> 36.3 | D22: {=_xlfn.XLOOKUP($A22,[1]MedicHistory!A:A,[1]MedicHistory!C:C,"")} -> 11.5 | E22: =_xlfn.XLOOKUP($A22,[1]MedicHistory!A:A,[1]MedicHistory!D:D,"") -> yes | F22: =_xlfn.XLOOKUP($A22,[1]MedicHistory!A:A,[1]MedicHistory!E:E,"") -> No | G22: =_xlfn.XLOOKUP($A22,[1]MedicHistory!A:A,[1]MedicHistory!F:F,"") -> No | H22: 0 | I22: =_xlfn.XLOOKUP($A22,[1]MedicHistory!A:A,[1]MedicHistory!H:H,"") -> yes | J22: =_xlfn.XLOOKUP($A22,[1]MedicHistory!A:A,[1]MedicHistory!K:K,"") -> Diabetic | K22: =_xlfn.XLOOKUP($A22,[1]MedicHistory!A:A,[1]MedicHistory!I:I,"") -> Obisity | L22: =_xlfn.XLOOKUP($A22,[1]Hospitalisation!A:A,[1]Hospitalisation!C:C,"") -> 47403.88 | M22: =_xlfn.XLOOKUP($A22,[1]Hospitalisation!A:A,[1]Hospitalisation!I:I,"") -> tier - 1 | N22: =_xlfn.XLOOKUP($A22,[1]Hospitalisation!A:A,[1]Hospitalisation!J:J,"") -> tier - 3 | O22: =_xlfn.XLOOKUP($A22,[1]Hospitalisation!A:A,[1]Hospitalisation!K:K,"") -> R1011 | P22: =_xlfn.XLOOKUP($A22,[1]Hospitalisation!A:A,[1]Hospitalisation!L:L,"") -> 51 | Q22: =_xlfn.XLOOKUP($A22,[1]Hospitalisation!A:A,[1]Hospitalisation!M:M,"") -> 26097
A23: Id22 | B23: =_xlfn.XLOOKUP(A23,[1]Customer!A:A,[1]Customer!C:C,"") -> Madelyn | C23: {=_xlfn.XLOOKUP($A23,[1]MedicHistory!A:A,[1]MedicHistory!B:B,"")} -> 32.2 | D23: {=_xlfn.XLOOKUP($A23,[1]MedicHistory!A:A,[1]MedicHistory!C:C,"")} -> 6.22 | E23: =_xlfn.XLOOKUP($A23,[1]MedicHistory!A:A,[1]MedicHistory!D:D,"") -> yes | F23: =_xlfn.XLOOKUP($A23,[1]MedicHistory!A:A,[1]MedicHistory!E:E,"") -> No | G23: =_xlfn.XLOOKUP($A23,[1]MedicHistory!A:A,[1]MedicHistory!F:F,"") -> No | H23: =_xlfn.XLOOKUP($A23,[1]MedicHistory!A:A,[1]MedicHistory!G:G,"") -> 2 | I23: =_xlfn.XLOOKUP($A23,[1]MedicHistory!A:A,[1]MedicHistory!H:H,"") -> yes | J23: =_xlfn.XLOOKUP($A23,[1]MedicHistory!A:A,[1]MedicHistory!K:K,"") -> Prediabetic | K23: =_xlfn.XLOOKUP($A23,[1]MedicHistory!A:A,[1]MedicHistory!I:I,"") -> Obisity | L23: =_xlfn.XLOOKUP($A23,[1]Hospitalisation!A:A,[1]Hospitalisation!C:C,"") -> 47305.31 | M23: =_xlfn.XLOOKUP($A23,[1]Hospitalisation!A:A,[1]Hospitalisation!I:I,"") -> tier - 2 | N23: =_xlfn.XLOOKUP($A23,[1]Hospitalisation!A:A,[1]Hospitalisation!J:J,"") -> tier - 1 | O23: =_xlfn.XLOOKUP($A23,[1]Hospitalisation!A:A,[1]Hospitalisation!K:K,"") -> R1011 | P23: =_xlfn.XLOOKUP($A23,[1]Hospitalisation!A:A,[1]Hospitalisation!L:L,"") -> 61 | Q23: =_xlfn.XLOOKUP($A23,[1]Hospitalisation!A:A,[1]Hospitalisation!M:M,"") -> 22558
